Workbook

Sheet Requirements map
A1: Req ID | B1: Module | C1: Priority | D1: Requirement | E1: What we built | F1: Portal screen | G1: Workspace | H1: Code | I1: How a user reaches it | J1: Test cases | K1: Result | L1: Explanation / demo example
A2: G-1 | B2: CGF | C2: Mandatory | D2: The system shall provide a centralized, searchable repository of every committee and governance forum, holding forum details, charter documents and associated metadata. Access, visibility and permitted actions shall be governed by role-based access control. | E2: Governance Forum with DocPerm rows; /forums register and /forum detail over the permission-checked REST API; www/forum.py throws for a viewer without read access and offers Edit only with write permission. | F2: /forums /forum?name=… | G2: /app/governance-forum — Governance workspace | H2: consilium/www/forum.py (portal page) consilium/www/forums.py (portal page) consilium/governance/doctype/governance_forum/governance_forum.py (Governance Forum) consilium/governance/inventory.py (module under the cited tests) | I2: (a) Through a purpose-built portal screen | J2: governance.tests.test_entities.TestGovernanceEntities.* (all 19) governance.tests.test_inventory.TestSearchAndFilter.test_search_respects_permissions consilium_core.tests.test_portal_pages.TestReaderWithoutAccess.* (all 2) | K2: ✅ | L2: 14 forums, from FRM-2026-00001 Board of Directors down to working groups (FRM-2026-00013).
A3: G-2 | B3: CGF | C3: Mandatory | D3: The system shall provide advanced search and filtering of forums by any indexed metadata field. | E3: /forums filters by type, status, cadence, risk category, operating group and standing, plus the four multi-valued dimensions (inventory.inventory_filters, inventory.tagged_forum_names, intersecting). Free-text search over name, code and mandate, also taken from ?q=. The header's global search finds a forum by identifier or name from any page (consilium_core/search.py). Retired taxonomy values are marked, not offered as new. Paged server-side, with Export CSV. | F3: /forums | G3: /app/governance-forum — Governance workspace | H3: consilium/governance/inventory.py → inventory_filters() consilium/governance/inventory.py → tagged_forum_names() consilium/consilium_core/search.py consilium/www/forums.py (portal page) consilium/governance/doctype/governance_forum/governance_forum.py (Governance Forum) | I3: (a) Through a purpose-built portal screen | J3: governance.tests.test_inventory.TestSearchAndFilter.* (all 4) governance.tests.test_governance_gaps.TestInventoryReads.test_tagged_filters_intersect governance.tests.test_governance_gaps.TestInventoryReads.test_tagged_names_respect_permission governance.tests.test_governance_gaps.TestInventoryReads.test_filter_values_include_retired_ones_marked consilium_core.tests.test_global_search.TestGlobalSearch.* (all 9) | K3: ✅ | L3: /forums?standing=overdue lists FRM-2026-00008 Model Risk Committee (review due 2026-08-14).
A4: G-3 | B4: CGF | C4: Mandatory | D4: The system shall allow a forum to be tagged with controlled metadata drawn from standard taxonomies, with dependent-field behaviour and dropdown-controlled selection. Minimum attributes: forum identifier, name, type, description, meeting cadence, chair, primary risk category, legal entity, owning organisation (operating group) and owning organisation (line of business). | E4: Link fields plus four multi-select child tables (business unit, risk type, legal entity, jurisdiction). Operating-group and line-of-business validation. Captured in /create-forum and on desk; shown on /forum. Retired values are not offered (taxonomy standard_queries hook). | F4: /create-forum /forum?name=… | G4: /app/governance-forum — Governance workspace | H4: consilium/www/create_forum.py (portal page) consilium/www/forum.py (portal page) consilium/consilium_core/taxonomy.py (module under the cited tests) consilium/governance/doctype/governance_forum/governance_forum.py (Governance Forum) | I4: (a) Through a purpose-built portal screen | J4: governance.tests.test_entities.TestGovernanceEntities.test_four_dimensions_are_multi_valued_and_two_are_not governance.tests.test_entities.TestGovernanceEntities.test_the_owning_organisation_must_be_an_operating_group governance.tests.test_entities.TestGovernanceEntities.test_a_line_of_business_must_sit_under_its_operating_group consilium_core.tests.test_entities.TestTaxonomies.* (all 9) consilium_core.tests.test_taxonomy.TestActiveOnlySearch.* (all 6) | K4: ✅ | L4: FRM-2026-00007 Technology and Cyber Risk Committee: type MGMT_CTTE, regulatory-required, 2 business units and 3 risk types.
A5: G-4 | B5: CGF | C5: Mandatory | D5: The system shall allow a forum to be mapped to related forums (upstream and downstream), to be flagged as regulatory-required with dependent capture of the applicable regulatory requirements. | E5: parent_forum, Forum Link (upstream and downstream), and Forum Regulatory Requirement, required when the flag is set. inventory.interconnectivity is drawn as SVG on /forum (Linkages tab). Links are edited on desk. | F5: /forum?name=… | G5: /app/governance-forum → 'Forum Link' table /app/governance-forum → 'Forum Regulatory Requirement' table | H5: consilium/governance/inventory.py → interconnectivity() consilium/www/forum.py (portal page) | I5: (a) Through a purpose-built portal screen | J5: governance.tests.test_entities.TestGovernanceEntities.test_regulatory_detail_becomes_required_when_the_flag_is_set governance.tests.test_entities.TestGovernanceEntities.test_a_forum_cannot_be_its_own_ancestor governance.tests.test_entities.TestGovernanceEntities.test_a_link_takes_its_direction_from_the_field_it_sits_in governance.tests.test_entities.TestGovernanceEntities.test_a_forum_cannot_link_to_itself governance.tests.test_inventory.TestRelationships.* (all 2) | K5: ✅ | L5: 15 Forum Link rows. FRM-2026-00005 Executive Risk Committee answers to FRM-2026-00004 and FRM-2026-00002 and has five sub-committees. 7 regulatory-required forums, for example FRM-2026-00010 with 2 requirements.
A6: G-5 | B6: CGF | C6: Mandatory | D6: The system shall support the committee formation process: structured intake, evaluation against defined criteria, capture of approval evidence, exception handling and status tracking. Evaluation criteria: gap in risk or governance coverage; duplication with existing forums; clear escalation and reporting pathways; alignment with the risk management framework, risk taxonomy and policy structure; resource feasibility. Charter drafts must be reviewable by the Risk Governance Office for completeness and appropriateness before approval. Acceptable approval evidence includes email, meeting minutes and signed documents. Disputes and exceptions resolve through the Head of Risk Governance. | E6: Committee Formation Request + Formation Evaluation (5 criteria seeded) + formation.py. /create-forum → /formation-requests → /formation-request covers findings, return and respond, approval steps, exception to the designated authority, charter challenge, approve, reject and withdraw. Approval creates a draft forum. Gap: Charter Approval Evidence rows are captured on desk only (DK-1 is in the trace). | F6: /create-forum /formation-requests /formation-request?name=… | G6: /app/committee-formation-request — Governance workspace /app/committee-formation-request → 'Formation Evaluation' table /app/committee-charter → 'Charter Approval Evidence' table | H6: consilium/governance/formation.py consilium/www/create_forum.py (portal page) consilium/www/formation_requests.py (portal page) consilium/www/formation_request.py (portal page) consilium/governance/doctype/committee_formation_request/committee_formation_request.py (Committee Formation Request) | I6: (a) Through a purpose-built portal screen | J6: governance.tests.test_formation.* (all 27) governance.tests.test_formation_portal.* (all 35) | K6: ✅ | L6: One request at each stage: CFR-2026-00006 Draft; 00004 Under Evaluation; 00003 Returned To Originator; 00002 Pending Approval; 00005 Rejected; 00001 Approved → FRM-2026-00014 Data Governance Council, with bypass EXCA-00001.
A7: G-6 | B7: CGF | C7: Mandatory | D7: The system shall support administratively configurable automated workflows for establishing, maintaining and disbanding forums, including approvals and escalations, without custom development. | E7: Formation Approval Route (steps, sequence and mode as data); Workflow State Flag (130 rows); Watched Field Set; disbandment trigger scenarios and approver roles are select options. Nothing branches on a state label. All on desk. | F7: — (no portal screen) | G7: /app/formation-approval-route — Governance workspace /app/workflow-state-flag — Consilium Administration workspace /app/watched-field-set — Consilium Administration workspace | H7: consilium/governance/doctype/formation_approval_route/formation_approval_route.py (Formation Approval Route) consilium/consilium_core/doctype/workflow_state_flag/workflow_state_flag.py (Workflow State Flag) consilium/consilium_core/doctype/watched_field_set/watched_field_set.py (Watched Field Set) consilium/governance/formation.py (module under the cited tests) consilium/consilium_core/state_flags.py (module under the cited tests) consilium/governance/lifecycle.py (module under the cited tests) | I7: (b) Through the desk, configuration or a scheduled job — by design | J7: governance.tests.test_formation.TestApprovalRoute.test_the_steps_are_configuration governance.tests.test_formation.TestApprovalRoute.test_a_route_change_changes_the_steps_without_a_deployment consilium_core.tests.test_state_flags.TestStateFlags.* (all 7) governance.tests.test_lifecycle.TestStateFlags.* (all 3) governance.tests.test_lifecycle.TestWatchedFields.* (all 5) | K7: ✅ | L7: "Standard Formation Approval" route (request type Any). CFR-2026-00002 shows the three steps it raised.
A8: G-7 | B8: CGF | C8: Mandatory | D8: The system shall prevent progression of a formation request when required information, approvals or evidence are incomplete or inconsistent. It shall validate intake completeness, check the request against the existing forum inventory for overlap or conflict, allow review and challenge of the draft charter before the requester seeks final approval, and validate submitted approvals against the intake record and charter before the forum inventory is updated. | E8: formation.approval_blockers covers: unassessed criteria; completeness confirmation; undecided steps; refused steps not bypassed; and an uncleared charter challenge (charters.uncleared_challenges). The challenge is recorded on /formation-request (charters.record_charter_challenge). An open challenge also blocks a favourable compliance decision (lifecycle.refuse_standing_over_open_challenge). Gap: the charter's approval evidence (in charters.clearance_blockers) is shown on /forum but is not a formation approval blocker. | F8: /formation-request?name=… /forum?name=… | G8: /app/committee-formation-request — Governance workspace /app/committee-charter — Governance workspace /app/governance-forum — Governance workspace | H8: consilium/governance/formation.py → approval_blockers() consilium/governance/charters.py → uncleared_challenges() consilium/governance/charters.py → record_charter_challenge() consilium/governance/lifecycle.py → refuse_standing_over_open_challenge() consilium/governance/charters.py → clearance_blockers() consilium/www/formation_request.py (portal page) consilium/www/forum.py (portal page) consilium/governance/doctype/committee_formation_request/committee_formation_request.py (Committee Formation Request) consilium/governance/doctype/committee_charter/committee_charter.py (Committee Charter) consilium/governance/doctype/governance_forum/governance_forum.py (Governance Forum) | I8: (a) Through a purpose-built portal screen | J8: governance.tests.test_formation.TestIntake.test_submission_runs_the_overlap_check governance.tests.test_formation.TestEvaluation.* (all 4) governance.tests.test_governance_gaps.TestFormationCharterGate.* (all 2) governance.tests.test_governance_gaps.TestStandingGate.* (all 3) governance.tests.test_wave3_governance.TestCharterChallengeOnTheRequest.* (all 2) governance.tests.test_charters.TestEffectiveChallenge.* (all 4) | K8: ✅ | L8: CFR-2026-00002 is held by CHT-2026-00014 "Changes Requested" and by an open Delegating Authority step. CHT-2026-00007 (FRM-2026-00007) "Changes Requested".
A9: G-8 | B9: CGF | C9: Mandatory | D9: The system shall support a multi-step approval process across stakeholders and roles, with sequential or parallel approvals, capturing charter approval. Approval paths may differ by materiality of change and by forum type. | E9: Route steps become Core Approval Decisions. Sequential order is enforced in approvals.record_decision (waiting_on, is_turn). Parallel steps and peers sharing a sequence number do not wait. Role-based steps form a queue. Steps are decided on /formation-request by the assignee, a queue member or a delegate. A bypass needs an Exception Authorisation, waives only its own step, and cannot be made by the step's own holder. Missing: the path cannot differ by forum type or by materiality of change. formation.resolve_route selects only by request_type (Any, Create, Modify, Retire), and Formation Approval Route has no forum-type or materiality field. | F9: /formation-request?name=… | G9: /app/approval-decision — Consilium Administration workspace /app/exception-authorisation — Consilium Administration workspace /app/formation-approval-route — Governance workspace | H9: consilium/consilium_core/approvals.py → record_decision() consilium/consilium_core/approvals.py → waiting_on() consilium/consilium_core/approvals.py → is_turn() consilium/governance/formation.py → resolve_route() consilium/www/formation_request.py (portal page) consilium/consilium_core/doctype/approval_decision/approval_decision.py (Approval Decision) consilium/consilium_core/doctype/exception_authorisation/exception_authorisation.py (Exception Authorisation) consilium/governance/doctype/formation_approval_route/formation_approval_route.py (Formation Approval Route) | I9: (d) Not implemented, wholly or in a mandatory clause | J9: governance.tests.test_formation.TestApprovalRoute.* (all 5) governance.tests.test_formation_portal.TestApprovalThroughThePortal.* (all 5) consilium_core.tests.test_core_controls_wave3.TestSequentialApprovals.* (all 6) governance.tests.test_wave3_governance.TestFormationStepOrder.* (all 4) governance.tests.test_w3_guides.TestABypassWaivesOnlyItsOwnStep.* (all 1) governance.tests.test_w3_guides.TestNobodyBypassesTheirOwnStep.* (all 2) governance.tests.test_w3_guides.TestARoleIsAQueue.* (all 5) consilium_core.tests.test_services.TestApprovals.* (all 5) | K9: ✅ (not the path-selection clause) | L9: CFR-2026-00002: Risk Governance Office Evaluation (seq 1) approved, Sponsor Endorsement (seq 2) approved, Delegating Authority (seq 2) pending. CFR-2026-00001: Sponsor step bypassed under EXCA-00001.
A10: G-9 | B10: CGF | C10: Mandatory | D10: The system shall track every change to a forum, maintain complete history, and log every user action with a timestamp and attributed actor. Prior versions shall be archivable and viewable. The system shall additionally allow an authorised user to revert a forum record to a previous version. | E10: A revision.snapshot doc event on Governance Forum writes a version chain. /forum History tab offers a revision history with Revert (revision.history and revision.revert: reason required, governance office only; lifecycle and derived fields are never restored; reverting a watched field sends the forum back for review). Record history (evidence.record_history, now including notifications) and an evidence-pack ZIP with a SHA-256 manifest (evidence.export_pack). | F10: /forum?name=… | G10: /app/governance-forum — Governance workspace | H10: consilium/consilium_core/revision.py → snapshot() consilium/consilium_core/revision.py → history() consilium/consilium_core/revision.py → revert() consilium/consilium_core/evidence.py → record_history() consilium/consilium_core/evidence.py → export_pack() consilium/www/forum.py (portal page) consilium/governance/doctype/governance_forum/governance_forum.py (Governance Forum) consilium/consilium_core/versioning.py (module under the cited tests) | I10: (a) Through a purpose-built portal screen | J10: consilium_core.tests.test_revision.TestForumRevision.* (all 5) governance.tests.test_governance_gaps.TestForumRevisionCard.* (all 1) consilium_core.tests.test_core_controls_wave3.TestHistoryAndEvidencePack.* (all 4) consilium_core.tests.test_versioning.TestVersioning.* (all 9) consilium_core.tests.test_entities.TestEntityStructure.test_governed_entities_keep_their_change_history | K10: ✅ | L10: VREV-00001: FRM-2026-00010 Asset-Liability Committee reverted to DVER-00109 with a justification. 40 forum versions.
A11: G-10 | B11: CGF | C11: Mandatory | D11: The system shall support periodic review schedules including self-assessments, charter reviews and monitoring activities. It shall enforce an annual attestation, conducted in the first quarter, requiring Committee Chairs, Committee Secretaries and Forum Owners to review and confirm the accuracy of the forum inventory. | E11: Attestation engine with inventory and dual-review campaign types (reviews.open_inventory_attestation; attesting seats CHAIR, SECRETARY, FORUM_OWNER have can_attest). The office opens campaigns and generates tasks from /attestation-campaigns (reviews.open_forum_campaign, generate_forum_campaign_tasks). Tasks are answered and counter-signed in /tasks. Reminders follow each campaign's schedule (reminders.remind_attestation_campaigns, daily). The annual review is run from the forum (/forum-review#annual-review). The overdue chase goes to owners (reminders.remind_forum_reviews). last_attested_on is stamped. Missing: nothing enforces or schedules the first quarter. No job opens the Q1 campaign or flags a year with none. The screen defaults the due date to today + 45 days and accepts any dates. | F11: /attestation-campaigns /tasks /forum-review#annual-review | G11: /app/attestation-campaign — Consilium Administration workspace /app/forum-compliance-review — Governance workspace | H11: consilium/governance/reviews.py → open_inventory_attestation() consilium/governance/reviews.py → open_forum_campaign() consilium/governance/reviews.py → generate_forum_campaign_tasks() consilium/consilium_core/reminders.py → remind_attestation_campaigns() consilium/consilium_core/reminders.py → remind_forum_reviews() consilium/www/attestation_campaigns.py (portal page) consilium/www/tasks.py (portal page) consilium/consilium_core/attestation.py (module under the cited tests) consilium/consilium_core/inbox.py (module under the cited tests) consilium/governance/lifecycle.py (module under the cited tests) consilium/governance/inventory.py (module under the cited tests) consilium/consilium_core/doctype/attestation_campaign/attestation_campaign.py (Attestation Campaign) consilium/governance/doctype/forum_compliance_review/forum_compliance_review.py (Forum Compliance Review) | I11: (d) Not implemented, wholly or in a mandatory clause | J11: consilium_core.tests.test_attestation.TestAttestation.* (all 13) consilium_core.tests.test_attestation.TestUnconfiguredRecordsDoNotStopACampaign.* (all 3) consilium_core.tests.test_inbox.TestInboxAttestation.* (all 8) consilium_core.tests.test_inbox.TestSecondSignature.* (all 3) consilium_core.tests.test_inbox.TestCampaignAdministration.* (all 5) consilium_core.tests.test_w3_guides_core.TestCampaignReminderSchedule.* (all 4) consilium_core.tests.test_reminders.TestForumReviewReminders.* (all 1) governance.tests.test_lifecycle.TestAnnualReview.* (all 4) governance.tests.test_w3_guides.TestAnnualReviewFromTheForum.* (all 4) governance.tests.test_inventory.TestAttestationStamp.* (all 3) | K11: ✅ (not the Q1 clause) | L11: ACAM-00002 "Forum inventory attestation 2026": 22 attested, 3 with exceptions, 3 declined, 11 pending. It opened 2026-08-04, due 2026-10-03, so outside Q1. ACAM-00003 dual review; ACAM-00001 (2025) closed. Annual reviews FCR-2026-00015/16/17.
A12: G-11 | B12: CGF | C12: Mandatory | D12: The system shall provide a configurable disbandment workflow covering trigger scenarios (annual inventory review, self-assessment outcome, charter review, completion of mandate), validation of closure approvals from the delegating authority, sponsor, chair and — where applicable — the jurisdictional Chief Risk Officer, and capture of a formal disbandment plan as an uploaded, tracked artefact. | E12: /forum-disband (linked from /forum): lifecycle.raise_disbandment_plan (the governance office; five trigger scenarios; delegating authority, sponsor and chair required, jurisdictional CRO optional); attach_disbandment_file (only a file attached to this plan); record_disbandment_decision (approver or delegate); execute_forum_disbandment (waits for every approval; the forum becomes inactive, never deleted). | F12: /forum-disband?name=… /forum?name=… | G12: /app/disbandment-plan — Governance workspace /app/governance-forum — Governance workspace | H12: consilium/governance/lifecycle.py → raise_disbandment_plan() consilium/governance/lifecycle.py → attach_disbandment_file() consilium/governance/lifecycle.py → record_disbandment_decision() consilium/governance/lifecycle.py → execute_forum_disbandment() consilium/www/forum_disband.py (portal page) consilium/www/forum.py (portal page) consilium/governance/doctype/disbandment_plan/disbandment_plan.py (Disbandment Plan) consilium/governance/doctype/governance_forum/governance_forum.py (Governance Forum) | I12: (a) Through a purpose-built portal screen | J12: governance.tests.test_governance_gaps.TestDisbandmentPortal.* (all 8) governance.tests.test_lifecycle.TestDisbandment.* (all 5) governance.tests.test_entities.TestGovernanceEntities.test_a_disbandment_plan_needs_the_approvals_it_requires governance.tests.test_formation_portal.TestComplianceReviewThroughThePortal.test_a_disbanded_forum_is_not_reviewed_again | K12: ✅ | L12: FDIS-2026-00001: FRM-2026-00012 Outsourcing Oversight Forum disbanded 2026-04-21, successor FRM-2026-00013. FDIS-2026-00002 (FRM-2026-00013) live: delegating authority approved, sponsor and chair pending. Neither demo plan has a plan file attached.
... A72: O-7 | B72: Supplementary | C72: Supplementary | D72: Real-time regulatory updates, predictive analytics for emerging risks and automated governance risk assessment. | E72: /regulatory-updates: recent changes, citing documents and forums, rule-based candidate documents and sections; record_change saves through the Regulatory Requirement controller, whose fan-out tells owners of citing documents and forums (P-6); file import through /imports with profile IMPP-00001 and policy.regulatory_import.prepare_changes, same fan-out; optional AI suggestions recorded and applied only on a person's accept (decide, AI Suggestion Acceptance with version). /emerging-risks: trends (slope, z-score) and leading indicators over escalations, violations, monitoring and SLA breaches. Governance risk scores with configurable weights on /governance-gaps (ai.scoring.assess). Same guard and client as O-6. | F72: /regulatory-updates /imports /emerging-risks /governance-gaps | G72: /app/regulatory-requirement — Consilium Administration workspace /app/ai-suggestion-acceptance desk button — consilium/governance/doctype/forum_meeting/forum_meeting.js | H72: consilium/consilium_core/ai/regulatory.py → record_change() consilium/consilium_core/ai/regulatory.py → decide() consilium/www/regulatory_updates.py (portal page) consilium/www/imports.py (portal page) consilium/www/emerging_risks.py (portal page) consilium/www/governance_gaps.py (portal page) consilium/consilium_core/doctype/regulatory_requirement/regulatory_requirement.py (Regulatory Requirement) consilium/consilium_core/doctype/ai_suggestion_acceptance/ai_suggestion_acceptance.py (AI Suggestion Acceptance) | I72: (a) Through a purpose-built portal screen | J72: consilium_core.tests.test_ai_features.TestRegulatory.* (all 8) consilium_core.tests.test_ai_features.TestTrends.* (all 4) consilium_core.tests.test_ai_features.TestScoring.* (all 3) consilium_core.tests.test_ai_features.TestPages.* (all 1) consilium_core.tests.test_regulatory_change.TestRegulatoryChangeFanOut.* (all 6) consilium_core.tests.test_integrations.TestHorizonScanning.* (all 3) | K72: ✅ (AI suggestions tested against a stub endpoint only) | L72: REQ_OP_RESILIENCE changed 2026-09-18, cited by GDOC-00007, owner notified; 12 requirements; /emerging-risks 7 rising series, 7 indicators; scores for 13 forums and 14 policies. The AI endpoint is connected (see O-6), but no regulatory suggestion has been requested through it on the demo site. The horizon-scanning platform is reached through /horizon-scanning.

Sheet Summary
A1: Consilium — requirements coverage
A3: Generated on | B3: 2026-09-18 13:07
A4: Measured on (per source) | B4: 2026-09-18
A5: Source | B5: docs/delivery/REQUIREMENTS-COVERAGE.md (matrix); docs/product/01-requirements-baseline.md (statements); docs/delivery/EPICS.md (stories)
A6: Git commit | B6: 9abaca6 (2026-09-18) — working tree has uncommitted changes
A7: Coverage source state | B7: modified since last commit; sha256 14f9838e73e092bc…
A8: Test run (per source) | B8: Ran 1453 tests, OK — 1453 passed, 0 failed
A9: Generator | B9: scripts/coverage_to_xlsx.py — regenerate after editing the Markdown; do not hand-edit
A11: Reachability class by module (live formulas over 'All requirements') | H11: As stated in the source's §2 summary
A12: Module | B12: (a) Portal | C12: (b) Desk/config | D12: (c) Partly | E12: (d) Not impl. | F12: Total | H12: a | I12: b | J12: c | K12: d | L12: Total | M12: Agrees? | O12: Chart data | P12: (a) | Q12: (b) | R12: (c) | S12: (d)
A13: CGF — Governance | B13: =COUNTIFS('All requirements'!$B$2:$B$500,"CGF",'All requirements'!$H$2:$H$500,"a") | C13: =COUNTIFS('All requirements'!$B$2:$B$500,"CGF",'All requirements'!$H$2:$H$500,"b") | D13: =COUNTIFS('All requirements'!$B$2:$B$500,"CGF",'All requirements'!$H$2:$H$500,"c") | E13: =COUNTIFS('All requirements'!$B$2:$B$500,"CGF",'All requirements'!$H$2:$H$500,"d") | F13: =COUNTIFS('All requirements'!$B$2:$B$500,"CGF") | H13: 11 | I13: 1 | J13: 4 | K13: 3 | L13: 19 | M13: =IF(COUNT(H13:L13)=0,"not stated",IF(AND(B13=H13,C13=I13,D13=J13,E13=K13,F13=L13),"Yes","NO")) | O13: CGF | P13: =B13 | Q13: =C13 | R13: =D13 | S13: =E13
A14: POL — Policy | B14: =COUNTIFS('All requirements'!$B$2:$B$500,"POL",'All requirements'!$H$2:$H$500,"a") | C14: =COUNTIFS('All requirements'!$B$2:$B$500,"POL",'All requirements'!$H$2:$H$500,"b") | D14: =COUNTIFS('All requirements'!$B$2:$B$500,"POL",'All requirements'!$H$2:$H$500,"c") | E14: =COUNTIFS('All requirements'!$B$2:$B$500,"POL",'All requirements'!$H$2:$H$500,"d") | F14: =COUNTIFS('All requirements'!$B$2:$B$500,"POL") | H14: 19 | I14: 3 | J14: 3 | K14: 1 | L14: 26 | M14: =IF(COUNT(H14:L14)=0,"not stated",IF(AND(B14=H14,C14=I14,D14=J14,E14=K14,F14=L14),"Yes","NO")) | O14: POL | P14: =B14 | Q14: =C14 | R14: =D14 | S14: =E14
A15: ESC — Escalation | B15: =COUNTIFS('All requirements'!$B$2:$B$500,"ESC",'All requirements'!$H$2:$H$500,"a") | C15: =COUNTIFS('All requirements'!$B$2:$B$500,"ESC",'All requirements'!$H$2:$H$500,"b") | D15: =COUNTIFS('All requirements'!$B$2:$B$500,"ESC",'All requirements'!$H$2:$H$500,"c") | E15: =COUNTIFS('All requirements'!$B$2:$B$500,"ESC",'All requirements'!$H$2:$H$500,"d") | F15: =COUNTIFS('All requirements'!$B$2:$B$500,"ESC") | H15: 13 | I15: 2 | J15: 2 | K15: 2 | L15: 19 | M15: =IF(COUNT(H15:L15)=0,"not stated",IF(AND(B15=H15,C15=I15,D15=J15,E15=K15,F15=L15),"Yes","NO")) | O15: ESC | P15: =B15 | Q15: =C15 | R15: =D15 | S15: =E15
A16: Mandatory total | B16: =COUNTIFS('All requirements'!$C$2:$C$500,"Mandatory",'All requirements'!$H$2:$H$500,"a") | C16: =COUNTIFS('All requirements'!$C$2:$C$500,"Mandatory",'All requirements'!$H$2:$H$500,"b") | D16: =COUNTIFS('All requirements'!$C$2:$C$500,"Mandatory",'All requirements'!$H$2:$H$500,"c") | E16: =COUNTIFS('All requirements'!$C$2:$C$500,"Mandatory",'All requirements'!$H$2:$H$500,"d") | F16: =COUNTIFS('All requirements'!$C$2:$C$500,"Mandatory") | H16: 43 | I16: 6 | J16: 9 | K16: 6 | L16: 64 | M16: =IF(COUNT(H16:L16)=0,"not stated",IF(AND(B16=H16,C16=I16,D16=J16,E16=K16,F16=L16),"Yes","NO")) | O16: Supplementary | P16: =B17 | Q16: =C17 | R16: =D17 | S16: =E17
A17: Supplementary (O-…) | B17: =COUNTIFS('All requirements'!$B$2:$B$500,"Supplementary",'All requirements'!$H$2:$H$500,"a") | C17: =COUNTIFS('All requirements'!$B$2:$B$500,"Supplementary",'All requirements'!$H$2:$H$500,"b") | D17: =COUNTIFS('All requirements'!$B$2:$B$500,"Supplementary",'All requirements'!$H$2:$H$500,"c") | E17: =COUNTIFS('All requirements'!$B$2:$B$500,"Supplementary",'All requirements'!$H$2:$H$500,"d") | F17: =COUNTIFS('All requirements'!$B$2:$B$500,"Supplementary") | H17: 5 | I17: 0 | J17: 0 | K17: 2 | L17: 7 | M17: =IF(COUNT(H17:L17)=0,"not stated",IF(AND(B17=H17,C17=I17,D17=J17,E17=K17,F17=L17),"Yes","NO"))
A18: Left: computed from the rows. Right: typed in the source's summary table and copied here as-is, so a stale summary in the Markdown shows up as 'NO'.
A20: Test evidence
A21: Evidence | B21: Mandatory | C21: Supplementary | D21: All
A22: At least one direct test, all passing | B22: =COUNTIFS('All requirements'!$C$2:$C$500,"Mandatory",'All requirements'!$N$2:$N$500,"Direct test") | C22: =COUNTIFS('All requirements'!$B$2:$B$500,"Supplementary",'All requirements'!$N$2:$N$500,"Direct test") | D22: =COUNTIFS('All requirements'!$N$2:$N$500,"Direct test")
A23: No direct test | B23: =COUNTIFS('All requirements'!$C$2:$C$500,"Mandatory",'All requirements'!$N$2:$N$500,"No direct test") | C23: =COUNTIFS('All requirements'!$B$2:$B$500,"Supplementary",'All requirements'!$N$2:$N$500,"No direct test") | D23: =COUNTIFS('All requirements'!$N$2:$N$500,"No direct test")
A24: Failing tests | B24: =COUNTIFS('All requirements'!$C$2:$C$500,"Mandatory",'All requirements'!$N$2:$N$500,"Failing test") | C24: =COUNTIFS('All requirements'!$B$2:$B$500,"Supplementary",'All requirements'!$N$2:$N$500,"Failing test") | D24: =COUNTIFS('All requirements'!$N$2:$N$500,"Failing test")
A25: …of which the pass is qualified (e.g. 'engine only') | B25: =COUNTIFS('All requirements'!$C$2:$C$500,"Mandatory",'All requirements'!$L$2:$L$500,"Pass (qualified)") | C25: =COUNTIFS('All requirements'!$B$2:$B$500,"Supplementary",'All requirements'!$L$2:$L$500,"Pass (qualified)") | D25: =COUNTIFS('All requirements'!$L$2:$L$500,"Pass (qualified)")
A26: Suite as measured: 1453 test methods run, outcome OK (typed from the source's Method section). A passing test proves only the part of a requirement it exercises.
A28: Backlog stories by status (live formulas over 'Epics')
A29: Status | B29: Stories
A30: Done | B30: =COUNTIFS('Epics'!$F$2:$F$1000,"Done*")
A31: Partial | B31: =COUNTIFS('Epics'!$F$2:$F$1000,"Partial*")
A32: In progress | B32: =COUNTIFS('Epics'!$F$2:$F$1000,"In progress*")
A33: Not started | B33: =COUNTIFS('Epics'!$F$2:$F$1000,"Not started*")
A34: Blocked | B34: =COUNTIFS('Epics'!$F$2:$F$1000,"Blocked*")
A35: No status recorded | B35: =COUNTIFS('Epics'!$A$2:$A$1000,"E*",'Epics'!$F$2:$F$1000,"")
A36: Total | B36: =COUNTIFS('Epics'!$A$2:$A$1000,"E*")
A38: Legend
A39: Class a | B39: Reachable through a purpose-built portal screen: the CS screens the trace names exist and do their part. Desk is used only where the trace names a DK surface.
A40: Class b | B40: Reachable through the desk, configuration or a scheduled job by design: the trace names only DK or BG surfaces for the key action.
A41: Class c | B41: Partly reachable. The backend exists, but a step has no screen, is desk-only where the trace calls for a custom screen, or is reachable only from code.
A42: Class d | B42: Not implemented, wholly or in a mandatory clause. The class is the weakest mandatory clause; the "What satisfies it" cell names the missing clause.
A43: Pass | B43: ✅ — the cited tests exist and passed in the measured run.
A44: Pass (qualified) | B44: ✅ with a qualifier such as '(engine only)' or '(flags only)': the tests pass but do not reach the missing clause.
A45: No direct test | B45: ⚠️ — nothing tests this requirement directly.
...

Sheet All requirements
A1: ID | B1: Module | C1: Priority | D1: Short title | E1: Baseline title | F1: Requirement (baseline statement) | G1: What satisfies it | H1: Class | I1: Class meaning | J1: Demo data / workflow | K1: Test(s) | L1: Result | M1: Result as measured | N1: Test evidence | O1: Cited test methods (est.) | P1: Planned satisfaction (baseline) | Q1: Δ decision | R1: Gap sections citing it | S1: Epics tracing it | T1: Stories tracing it
A2: G-1 | B2: CGF | C2: Mandatory | D2: Central forum repository, role-based access | E2: Forum Repository | F2: The system shall provide a centralized, searchable repository of every committee and governance forum, holding forum details, charter documents and associated metadata. Access, visibility and permitted actions shall be governed by role-based access control. | G2: Governance Forum with DocPerm rows; /forums register and /forum detail over the permission-checked REST API; www/forum.py throws for a viewer without read access and offers Edit only with write permission. | H2: a | I2: (a) Portal screen | J2: 14 forums, from FRM-2026-00001 Board of Directors down to working groups (FRM-2026-00013). | K2: governance.tests.test_entities.TestGovernanceEntities (all 19); governance.tests.test_inventory.TestSearchAndFilter.test_search_respects_permissions; consilium_core.tests.test_portal_pages.TestReaderWithoutAccess (all 2) | L2: Pass | M2: ✅ | N2: Direct test | O2: 25 | P2: Config — Governance Forum DocType, attachment handling and the permission engine are native; the register screen is a custom Bootstrap table. | S2: E6 | T2: 6
A3: G-2 | B3: CGF | C3: Mandatory | D3: Advanced search and filter | E3: Search and Retrieval | F3: The system shall provide advanced search and filtering of forums by any indexed metadata field. | G3: /forums filters by type, status, cadence, risk category, operating group and standing, plus the four multi-valued dimensions (inventory.inventory_filters, inventory.tagged_forum_names, intersecting). Free-text search over name, code and mandate, also taken from ?q=. The header's global search finds a forum by identifier or name from any page (consilium_core/search.py). Retired taxonomy values are marked, not offered as new. Paged server-side, with Export CSV. | H3: a | I3: (a) Portal screen | J3: /forums?standing=overdue lists FRM-2026-00008 Model Risk Committee (review due 2026-08-14). | K3: governance.tests.test_inventory.TestSearchAndFilter (all 4); governance.tests.test_governance_gaps.TestInventoryReads.test_tagged_filters_intersect, …test_tagged_names_respect_permission, …test_filter_values_include_retired_ones_marked; consilium_core.tests.test_global_search.TestGlobalSearch (all 9) | L3: Pass | M3: ✅ | N3: Direct test | O3: 19 | P3: Config + Build — native list filtering and report views on Desk; a hand-built filter/search/sort/paginate control on the custom Forum Register. | Q3: Δ | S3: E6, E35 | T3: 11
A4: G-3 | B4: CGF | C4: Mandatory | D4: Forum tagging with controlled taxonomies | E4: Forum Tagging | F4: The system shall allow a forum to be tagged with controlled metadata drawn from standard taxonomies, with dependent-field behaviour and dropdown-controlled selection. Minimum attributes: forum identifier, name, type, description, meeting cadence, chair, primary risk category, legal entity, owning organisation (operating group) and owning organisation (line of business). | G4: Link fields plus four multi-select child tables (business unit, risk type, legal entity, jurisdiction). Operating-group and line-of-business validation. Captured in /create-forum and on desk; shown on /forum. Retired values are not offered (taxonomy standard_queries hook). | H4: a | I4: (a) Portal screen | J4: FRM-2026-00007 Technology and Cyber Risk Committee: type MGMT_CTTE, regulatory-required, 2 business units and 3 risk types. | K4: test_entities.TestGovernanceEntities.test_four_dimensions_are_multi_valued_and_two_are_not, …test_the_owning_organisation_must_be_an_operating_group, …test_a_line_of_business_must_sit_under_its_operating_group; consilium_core.tests.test_entities.TestTaxonomies (all 9); consilium_core.tests.test_taxonomy.TestActiveOnlySearch (all 6) | L4: Pass | M4: ✅ | N4: Direct test | O4: 20 | P4: Config — Link fields to Core taxonomy DocTypes plus child multi-select tables. | Q4: Δ | S4: E3, E6 | T4: 11
A5: G-4 | B5: CGF | C5: Mandatory | D5: Forum mapping; regulatory-required with dependent capture | E5: Forum Mapping | F5: The system shall allow a forum to be mapped to related forums (upstream and downstream), to be flagged as regulatory-required with dependent capture of the applicable regulatory requirements. | G5: parent_forum, Forum Link (upstream and downstream), and Forum Regulatory Requirement, required when the flag is set. inventory.interconnectivity is drawn as SVG on /forum (Linkages tab). Links are edited on desk. | H5: a | I5: (a) Portal screen | J5: 15 Forum Link rows. FRM-2026-00005 Executive Risk Committee answers to FRM-2026-00004 and FRM-2026-00002 and has five sub-committees. 7 regulatory-required forums, for example FRM-2026-00010 with 2 requirements. | K5: test_entities.…test_regulatory_detail_becomes_required_when_the_flag_is_set, …test_a_forum_cannot_be_its_own_ancestor, …test_a_link_takes_its_direction_from_the_field_it_sits_in, …test_a_forum_cannot_link_to_itself; test_inventory.TestRelationships (all 2) | L5: Pass | M5: ✅ | N5: Direct test | O5: 6 | P5: Config — self-referencing child table Forum Link; Forum Regulatory Requirement child table gated on a check field. | S5: E6 | T5: 6
A6: G-5 | B6: CGF | C6: Mandatory | D6: Committee formation: intake, 5-criteria evaluation, evidence, exceptions, status | E6: Committee Formation | F6: The system shall support the committee formation process: structured intake, evaluation against defined criteria, capture of approval evidence, exception handling and status tracking. Evaluation criteria: gap in risk or governance coverage; duplication with existing forums; clear escalation and reporting pathways; alignment with the risk management framework, risk taxonomy and policy structure; resource feasibility. Charter drafts must be reviewable by the Risk Governance Office for completeness and appropriateness before approval. Acceptable approval evidence includes email, meeting minutes and signed documents. Disputes and exceptions resolve through the Head of Risk Governance. | G6: Committee Formation Request + Formation Evaluation (5 criteria seeded) + formation.py. /create-forum → /formation-requests → /formation-request covers findings, return and respond, approval steps, exception to the designated authority, charter challenge, approve, reject and withdraw. Approval creates a draft forum. Gap: Charter Approval Evidence rows are captured on desk only (DK-1 is in the trace). | H6: a | I6: (a) Portal screen | J6: One request at each stage: CFR-2026-00006 Draft; 00004 Under Evaluation; 00003 Returned To Originator; 00002 Pending Approval; 00005 Rejected; 00001 Approved → FRM-2026-00014 Data Governance Council, with bypass EXCA-00001. | K6: governance.tests.test_formation (all 27: TestIntake, TestEvaluation, TestReturnToOriginator, TestApprovalRoute, TestExceptionRoute, TestApprovalCreatesTheForum); governance.tests.test_formation_portal (all 35) | L6: Pass | M6: ✅ | N6: Direct test | O6: 64 | P6: Config + Build — Committee Formation Request with a configured multi-state workflow; Forum Evaluation child table; Committee Charter with attached approval evidence. Build: the gating logic that prevents progression. | Q6: Δ | S6: E7 | T6: 6
A7: G-6 | B7: CGF | C7: Mandatory | D7: Admin-configurable workflows, no code | E7: Configurable Automated Workflow | F7: The system shall support administratively configurable automated workflows for establishing, maintaining and disbanding forums, including approvals and escalations, without custom development. | G7: Formation Approval Route (steps, sequence and mode as data); Workflow State Flag (130 rows); Watched Field Set; disbandment trigger scenarios and approver roles are select options. Nothing branches on a state label. All on desk. | H7: b | I7: (b) Desk / config / job by design | J7: "Standard Formation Approval" route (request type Any). CFR-2026-00002 shows the three steps it raised. | K7: test_formation.TestApprovalRoute.test_the_steps_are_configuration, …test_a_route_change_changes_the_steps_without_a_deployment; consilium_core.tests.test_state_flags.TestStateFlags (all 7); governance.tests.test_lifecycle.TestStateFlags (all 3); test_lifecycle.TestWatchedFields (all 5) | L7: Pass | M7: ✅ | N7: Direct test | O7: 19 | P7: Native + Config — the framework's Workflow engine (states, transitions, role gates) is a configuration record, editable by an administrator. | Q7: Δ | S7: E7 | T7: 6
A8: G-7 | B8: CGF | C8: Mandatory | D8: Governance office controls: completeness, overlap check, charter challenge before approval, validate approvals | E8: Risk Governance Office Controls | F8: The system shall prevent progression of a formation request when required information, approvals or evidence are incomplete or inconsistent. It shall validate intake completeness, check the request against the existing forum inventory for overlap or conflict, allow review and challenge of the draft charter before the requester seeks final approval, and validate submitted approvals against the intake record and charter before the forum inventory is updated. | G8: formation.approval_blockers covers: unassessed criteria; completeness confirmation; undecided steps; refused steps not bypassed; and an uncleared charter challenge (charters.uncleared_challenges). The challenge is recorded on /formation-request (charters.record_charter_challenge). An open challenge also blocks a favourable compliance decision (lifecycle.refuse_standing_over_open_challenge). Gap: the charter's approval evidence (in charters.clearance_blockers) is shown on /forum but is not a formation approval blocker. | H8: a | I8: (a) Portal screen | J8: CFR-2026-00002 is held by CHT-2026-00014 "Changes Requested" and by an open Delegating Authority step. CHT-2026-00007 (FRM-2026-00007) "Changes Requested". | K8: test_formation.TestIntake.test_submission_runs_the_overlap_check; TestEvaluation (all 4); governance.tests.test_governance_gaps.TestFormationCharterGate (all 2), TestStandingGate (all 3); governance.tests.test_wave3_governance.TestCharterChallengeOnTheRequest (all 2); governance.tests.test_charters.TestEffectiveChallenge (all 4) | L8: Pass | M8: ✅ | N8: Direct test | O8: 19 | P8: Build — server-side validation on workflow transition; duplicate-detection query against the forum register; completeness gate on the evaluation child table. | S8: E7, E33 | T8: 7
A9: G-8 | B9: CGF | C9: Mandatory | D9: Multi-step, sequential or parallel approval; path by materiality and forum type | E9: Configurable Review and Approval Workflow | F9: The system shall support a multi-step approval process across stakeholders and roles, with sequential or parallel approvals, capturing charter approval. Approval paths may differ by materiality of change and by forum type. | G9: Route steps become Core Approval Decisions. Sequential order is enforced in approvals.record_decision (waiting_on, is_turn). Parallel steps and peers sharing a sequence number do not wait. Role-based steps form a queue. Steps are decided on /formation-request by the assignee, a queue member or a delegate. A bypass needs an Exception Authorisation, waives only its own step, and cannot be made by the step's own holder. Missing: the path cannot differ by forum type or by materiality of change. formation.resolve_route selects only by request_type (Any, Create, Modify, Retire), and Formation Approval Route has no forum-type or materiality field. | H9: d | I9: (d) Not implemented (whole or mandatory part) | J9: CFR-2026-00002: Risk Governance Office Evaluation (seq 1) approved, Sponsor Endorsement (seq 2) approved, Delegating Authority (seq 2) pending. CFR-2026-00001: Sponsor step bypassed under EXCA-00001. | K9: test_formation.TestApprovalRoute (all 5); test_formation_portal.TestApprovalThroughThePortal (all 5); consilium_core.tests.test_core_controls_wave3.TestSequentialApprovals (all 6); governance.tests.test_wave3_governance.TestFormationStepOrder (all 4); governance.tests.test_w3_guides.TestABypassWaivesOnlyItsOwnStep (all 1), TestNobodyBypassesTheirOwnStep (all 2), TestARoleIsAQueue (all 5); consilium_core.tests.test_services.TestApprovals (all 5) | L9: Pass (qualified) | M9: ✅ (not the path-selection clause) | N9: Direct test | O9: 37 | P9: Config + Build — workflow states and role-gated transitions; build for conditional path selection by change materiality. | R9: Class (d), No direct test | S9: E7 | T9: 6
A10: G-9 | B10: CGF | C10: Mandatory | D10: Full history, attributed; archivable prior versions; revert a forum record | E10: Version Control, Audit History and Accountability | F10: The system shall track every change to a forum, maintain complete history, and log every user action with a timestamp and attributed actor. Prior versions shall be archivable and viewable. The system shall additionally allow an authorised user to revert a forum record to a previous version. | G10: A revision.snapshot doc event on Governance Forum writes a version chain. /forum History tab offers a revision history with Revert (revision.history and revision.revert: reason required, governance office only; lifecycle and derived fields are never restored; reverting a watched field sends the forum back for review). Record history (evidence.record_history, now including notifications) and an evidence-pack ZIP with a SHA-256 manifest (evidence.export_pack). | H10: a | I10: (a) Portal screen | J10: VREV-00001: FRM-2026-00010 Asset-Liability Committee reverted to DVER-00109 with a justification. 40 forum versions. | K10: consilium_core.tests.test_revision.TestForumRevision (all 5); governance.tests.test_governance_gaps.TestForumRevisionCard (all 1); consilium_core.tests.test_core_controls_wave3.TestHistoryAndEvidencePack (all 4); consilium_core.tests.test_versioning.TestVersioning (all 9); consilium_core.tests.test_entities.TestEntityStructure.test_governed_entities_keep_their_change_history | L10: Pass | M10: ✅ | N10: Direct test | O10: 25 | P10: Native + Build — field-level version log and comment threads are native; revert is a build. | Q10: Δ | S10: E4, E30 | T10: 6
A11: G-10 | B11: CGF | C11: Mandatory | D11: Periodic reviews; annual Q1 inventory attestation by chairs, secretaries, owners | E11: Forum Maintenance | F11: The system shall support periodic review schedules including self-assessments, charter reviews and monitoring activities. It shall enforce an annual attestation, conducted in the first quarter, requiring Committee Chairs, Committee Secretaries and Forum Owners to review and confirm the accuracy of the forum inventory. | G11: Attestation engine with inventory and dual-review campaign types (reviews.open_inventory_attestation; attesting seats CHAIR, SECRETARY, FORUM_OWNER have can_attest). The office opens campaigns and generates tasks from /attestation-campaigns (reviews.open_forum_campaign, generate_forum_campaign_tasks). Tasks are answered and counter-signed in /tasks. Reminders follow each campaign's schedule (reminders.remind_attestation_campaigns, daily). The annual review is run from the forum (/forum-review#annual-review). The overdue chase goes to owners (reminders.remind_forum_reviews). last_attested_on is stamped. Missing: nothing enforces or schedules the first quarter. No job opens the Q1 campaign or flags a year with none. The screen defaults the due date to today + 45 days and accepts any dates. | H11: d | I11: (d) Not implemented (whole or mandatory part) | J11: ACAM-00002 "Forum inventory attestation 2026": 22 attested, 3 with exceptions, 3 declined, 11 pending. It opened 2026-08-04, due 2026-10-03, so outside Q1. ACAM-00003 dual review; ACAM-00001 (2025) closed. Annual reviews FCR-2026-00015/16/17. | K11: consilium_core.tests.test_attestation.TestAttestation (all 13), TestUnconfiguredRecordsDoNotStopACampaign (all 3); consilium_core.tests.test_inbox.TestInboxAttestation (all 8), TestSecondSignature (all 3), TestCampaignAdministration (all 5); consilium_core.tests.test_w3_guides_core.TestCampaignReminderSchedule (all 4); consilium_core.tests.test_reminders.TestForumReviewReminders (all 1); governance.tests.test_lifecycle.TestAnnualReview (all 4); governance.tests.test_w3_guides.TestAnnualReviewFromTheForum (all 4); test_inventory.TestAttestationStamp (all 3) | L11: Pass (qualified) | M11: ✅ (not the Q1 clause) | N11: Direct test | O11: 54 | P11: Build — the shared attestation campaign/task engine, with a CGF inventory campaign type; scheduled job generates tasks and reminders. | Q11: Δ | R11: Class (d), No direct test | S11: E8, E18, E28 | T11: 13
A12: G-11 | B12: CGF | C12: Mandatory | D12: Configurable disbandment: triggers, approvals, plan artefact | E12: Committee Disbanding | F12: The system shall provide a configurable disbandment workflow covering trigger scenarios (annual inventory review, self-assessment outcome, charter review, completion of mandate), validation of closure approvals from the delegating authority, sponsor, chair and — where applicable — the jurisdictional Chief Risk Officer, and capture of a formal disbandment plan as an uploaded, tracked artefact. | G12: /forum-disband (linked from /forum): lifecycle.raise_disbandment_plan (the governance office; five trigger scenarios; delegating authority, sponsor and chair required, jurisdictional CRO optional); attach_disbandment_file (only a file attached to this plan); record_disbandment_decision (approver or delegate); execute_forum_disbandment (waits for every approval; the forum becomes inactive, never deleted). | H12: a | I12: (a) Portal screen | J12: FDIS-2026-00001: FRM-2026-00012 Outsourcing Oversight Forum disbanded 2026-04-21, successor FRM-2026-00013. FDIS-2026-00002 (FRM-2026-00013) live: delegating authority approved, sponsor and chair pending. Neither demo plan has a plan file attached. | K12: governance.tests.test_governance_gaps.TestDisbandmentPortal (all 8); governance.tests.test_lifecycle.TestDisbandment (all 5); test_entities.…test_a_disbandment_plan_needs_the_approvals_it_requires; test_formation_portal.TestComplianceReviewThroughThePortal.test_a_disbanded_forum_is_not_reviewed_again | L12: Pass | M12: ✅ | N12: Direct test | O12: 17 | P12: Config + Build — terminal workflow state with its own approval path; Disbandment Plan DocType; build for the approval-completeness gate and the retention consequence. | S12: E8 | T12: 5
A13: G-12 | B13: CGF | C13: Mandatory | D13: Reporting and dashboards: status, coverage, compliance, performance; drill-down; export | E13: Reporting and Dashboards | F13: The system shall provide reporting and dashboards for oversight of forums enterprise-wide: status, coverage, compliance and performance metrics; filtering, aggregation and drill-down by forum type, status, legal entity, risk coverage, ownership and review or attestation status; current and historical views including forums in formation, active forums, upcoming reviews, overdue actions and service-level performance; export of reports and artefacts for management, audit and regulatory needs. | G13: /reports: forums awaiting review, overdue, regulatory-required, disbanded; by compliance status and by type; coverage matrix of risk category by owning group, with empty cells highlighted. Every figure links to the filtered /forums. Also /governance-gaps (ai.gaps.detect: coverage, forum, policy and regulatory gaps; ai.scoring.assess); /formation-requests for forums in formation; /attestation-campaigns board for attestation status. Export CSV on /forums exports the matching rows through the permission-checked list (up to 5,000 rows, formula-safe). Gap: no service-level performance for forums or formation (no SLA Definition targets either doctype). | H13: c | I13: (c) Partly reachable | J13: FRM-2026-00007 Non-Compliant; FRM-2026-00013 Pending; FRM-2026-00011 and FRM-2026-00014 Draft; FRM-2026-00012 Disbanded; FRM-2026-00008 overdue. | K13: consilium_core.tests.test_ai_features.TestGaps.test_forum_policy_regulatory_and_coverage_gaps_are_found; consilium_core.tests.test_ai_features.TestPages (all 1); consilium_core.tests.test_portal_pages.TestAdministrator.test_every_page_renders_with_its_key_sections | L13: Pass (qualified) | M13: ✅ (gap rules and page render only; no forum figure is tested) | N13: Direct test | O13: 6 | P13: Native + Build — native report builder, query reports, dashboard charts and export on Desk; custom Bootstrap dashboard screens for the daily-use views. | R13: Class (c), No direct test | S13: E10, E20 | T13: 9
A14: G-13 | B14: CGF | C14: Mandatory | D14: RBAC with delegates; groupings; nomination of delegates | E14: Role-Based Access Control | F14: The system shall provide role-based access for individuals and their delegates (Committee Secretary, Forum Owner, Reviewer, Approver, Viewer, Administrator). It shall support grouping users by role and attribute (line of business, first/second line of defence, legal, compliance, voting versus non-voting). Chairs, sponsors and secretaries shall be able to nominate delegates for administrative tasks. | G14: Roles (Committee Secretary, Forum Owner, Compliance Reviewer, Governance Viewer, Risk Governance Office, Consilium Administrator, Consilium Audit and others). Seat roles carry vote, quorum and attest flags. Authority Delegation with a validity window (delegation.resolve_actor). Seat delegates on Forum Membership. Gap: chairs and sponsors cannot nominate a delegate themselves. Only System Manager and Consilium Administrator may create Authority Delegation. Seat delegates are set on desk by the Committee Secretary or the governance office. | H14: c | I14: (c) Partly reachable | J14: 23 personas. ADEL-00001…00004 (ADEL-00002 expired). FMEM-00031 on FRM-2026-00005 has a standing delegate. | K14: consilium_core.tests.test_delegation.TestDelegation (all 13); consilium_core.tests.test_entities.TestPermissions (all 5); governance.tests.test_membership.TestDelegation (all 3); governance.tests.test_voting.TestDelegatedVoting (all 3); test_w3_guides.TestARoleIsAQueue (all 5) | L14: Pass | M14: ✅ | N14: Direct test | O14: 33 | P14: Native + Config + Build — native role/permission engine and user groups; forum-scoped accountability roles are modelled as membership rows; build for delegation validity windows. | Q14: Δ | R14: Class (c) | S14: E2, E9 | T14: 11
A15: G-14 | B15: CGF | C15: Mandatory | D15: Configurable, templated, automated notifications (approvals, reviews, escalations, meetings, attestation, charter reviews) | E15: Notifications | F15: The system shall send configurable, templated, automated notifications for approvals, reviews, escalations, meeting schedules, annual attestation and charter reviews. | G15: Notification Template per event (49, admin-editable per channel; notification.notify). There is an e-mail adapter over SMTP or Microsoft Graph, falling back to the record channel, with retry. Every caller now raises an event; none sends hard-coded text. Governance events: formation returned, approval requested, exception raised, approved and rejected; forum review recorded, returned for review and disbanded; disbandment approval requested (governance.disbandment.approval_requested, from lifecycle.raise_disbandment); forum review overdue; attestation open and second signature missing; attestation task reminder. Missing: no notification for meeting schedules or charter reviews (no event code, template or caller). | H15: d | I15: (d) Not implemented (whole or mandatory part) | J15: 201 dispatches: 178 EMAIL, 23 RECORD. For example "Formation approval requested" (8), "Compliance review recorded" (34). The 2 "Forum disbandment awaits your approval" dispatches were written by the demo load before that notice was templated. Reminder Log row for governance.forum_review.overdue on FRM-2026-00008. | K15: governance.tests.test_wave3_governance.TestTemplatedNotices (all 3); consilium_core.tests.test_notification_templates.TestSeeding (all 2), TestEventApi (all 10), TestTemplateFailures (all 5), TestEmailRetry (all 3); consilium_core.tests.test_notification.TestNotification (all 6); test_formation.TestReturnToOriginator.test_the_originator_is_notified; test_lifecycle.TestWatchedFields.test_compliance_is_notified_and_a_task_is_raised; governance.tests.test_governance_gaps.TestDisbandmentPortal.test_raising_names_g11s_approvers_and_asks_them | L15: Pass (qualified) | M15: ✅ (what exists; nothing tests the missing meeting and charter notices) | N15: Direct test | O15: 36 | P15: Native + Config + Build — native notification definitions and email queue; build for the pluggable channel abstraction. | Q15: Δ | R15: Class (d), No direct test | S15: E9, E19, E29, E36 | T15: 18
A16: G-15 | B16: CGF | C16: Mandatory | D16: Attach any documents, with version control and audit log; retain all | E16: Document Management | F16: The system shall allow documents to be attached without restriction on type or count — templates, charters and mandates, agendas, meeting minutes and related material — with version control, and shall show an audit log of all activity. All documents and history shall be retained. | G16: Native attachments and activity log. On /forum Documents: start a charter (charters.start_forum_charter) and take a new charter version with a change summary (charters.publish_charter_version, only a file attached to that charter; this reopens the challenge). Minutes are versioned through the desk button "Record minutes" (meetings.record_meeting_minutes). Meeting agenda file. Deletion guarded. | H16: a | I16: (a) Portal screen | J16: 14 charters, 17 charter versions (CHT-2026-00005, CHT-2026-00007 and CHT-2026-00011 have 2 each). 67 meetings, 38 with a minutes version (for example FMTG-2026-00035). | K16: governance.tests.test_governance_gaps.TestCharterPortal (all 9); governance.tests.test_charters.TestCharterVersions (all 2); governance.tests.test_regressions.TestMinutes (all 3) | L16: Pass | M16: ✅ | N16: Direct test | O16: 17 | P16: Native + Build — native attachment handling and activity log; build for the document version chain and its retention linkage. | Q16: Δ | S16: E5, E33 | T16: 6
